{"name": "test_fail", "status": "failed", "statusDetails": {"message": "AssertionError: assert False", "trace": "def test_fail():\n>       assert False\nE       assert False\n\ntests\\test_fail.py:4: AssertionError"}, "start": 1698248764115, "stop": 1698248764116, "uuid": "d2435991-fa0d-428b-98da-f94cc91181d2", "historyId": "1c6d798198e5fb12f50877ff5d2f655b", "testCaseId": "cd2384dd64342692c894db79d0a45ba3", "fullName": "tests.test_fail#test_fail", "labels": [{"name": "parentSuite", "value": "tests"}, {"name": "suite", "value": "test_fail"}, {"name": "host", "value": "DESKTOP-S15PP4S"}, {"name": "thread", "value": "9684-MainThread"}, {"name": "framework", "value": "pytest"}, {"name": "language", "value": "cpython3"}, {"name": "package", "value": "tests.test_fail"}]}